Workbook

Sheet Raw Data
A1: OrderID | B1: Date | C1: CustomerID | D1: Product | E1: Quantity | F1: UnitPrice | G1: ShippingAddress | H1: PaymentMethod | I1: OrderStatus | J1: TrackingNumber | K1: ItemsInCart | L1: CouponCode | M1: ReferralSource | N1: TotalPrice
A2: ORD200000 | B2: 44930 | C2: C72649 | D2: Monitor | E2: 5 | F2: 570.62 | G2: 928 Main St | H2: Debit Card | I2: Shipped | J2: TRK37947903 | K2: 7 | L2: SAVE10 | M2: Instagram | N2: 2853.1
A3: ORD200001 | B3: 45527 | C3: C75739 | D3: Phone | E3: 2 | F3: 151.35 | G3: 823 Main St | H3: Online | I3: Shipped | J3: TRK91186779 | K3: 3 | L3: SAVE10 | M3: Referral | N3: 302.7
A4: ORD200002 | B4: 45349 | C4: C81728 | D4: Tablet | E4: 5 | F4: 550.68 | G4: 512 Main St | H4: Credit Card | I4: Cancelled | J4: TRK42903982 | K4: 8 | L4: FREESHIP | M4: Email | N4: 2753.4
A5: ORD200003 | B5: 45214 | C5: C33540 | D5: Chair | E5: 1 | F5: 273.19 | G5: 275 Main St | H5: Debit Card | I5: Returned | J5: TRK62788070 | K5: 5 | L5: SAVE10 | M5: Facebook | N5: 273.19
A6: ORD200004 | B6: 45785 | C6: C81840 | D6: Printer | E6: 4 | F6: 626.01 | G6: 668 Main St | H6: Online | I6: Delivered | J6: TRK29241424 | K6: 8 | L6: SAVE10 | M6: Email | N6: 2504.04
A7: ORD200005 | B7: 45222 | C7: C37249 | D7: Phone | E7: 2 | F7: 245.86 | G7: 934 Main St | H7: Credit Card | I7: Shipped | J7: TRK72976927 | K7: 4 | L7: SAVE10 | M7: Instagram | N7: 491.72
A8: ORD200006 | B8: 45825 | C8: C83492 | D8: Laptop | E8: 1 | F8: 664.42 | G8: 986 Main St | H8: Gift Card | I8: Returned | J8: TRK96417362 | K8: 6 | L8: SAVE10 | M8: Facebook | N8: 664.42
A9: ORD200007 | B9: 45058 | C9: C41460 | D9: Monitor | E9: 5 | F9: 149.55 | G9: 706 Main St | H9: Cash | I9: Shipped | J9: TRK78809193 | K9: 9 | L9: FREESHIP | M9: Facebook | N9: 747.75
A10: ORD200008 | B10: 45749 | C10: C26817 | D10: Phone | E10: 2 | F10: 134.28 | G10: 904 Main St | H10: Gift Card | I10: Cancelled | J10: TRK61042692 | K10: 2 | M10: Email | N10: 268.56
A11: ORD200009 | B11: 45251 | C11: C31946 | D11: Desk | E11: 4 | F11: 509.38 | G11: 102 Main St | H11: Credit Card | I11: Shipped | J11: TRK33478363 | K11: 6 | L11: SAVE10 | M11: Google | N11: 2037.52
A12: ORD200010 | B12: 45289 | C12: C43443 | D12: Tablet | E12: 5 | F12: 625.97 | G12: 333 Main St | H12: Credit Card | I12: Returned | J12: TRK98859248 | K12: 9 | L12: WINTER15 | M12: Instagram | N12: 3129.85
A13: ORD200011 | B13: 45339 | C13: C93861 | D13: Monitor | E13: 3 | F13: 49.14 | G13: 831 Main St | H13: Online | I13: Returned | J13: TRK48234646 | K13: 7 | L13: SAVE10 | M13: Email | N13: 147.42
A14: ORD200012 | B14: 45580 | C14: C38785 | D14: Monitor | E14: 2 | F14: 180.5 | G14: 179 Main St | H14: Debit Card | I14: Pending | J14: TRK20419991 | K14: 6 | L14: FREESHIP | M14: Referral | N14: 361
A15: ORD200013 | B15: 45168 | C15: C88348 | D15: Laptop | E15: 3 | F15: 201.49 | G15: 903 Main St | H15: Credit Card | I15: Returned | J15: TRK81913874 | K15: 4 | L15: FREESHIP | M15: Facebook | N15: 604.47
A16: ORD200014 | B16: 45012 | C16: C98474 | D16: Tablet | E16: 2 | F16: 393.33 | G16: 980 Main St | H16: Debit Card | I16: Pending | J16: TRK79186539 | K16: 3 | L16: SAVE10 | M16: Instagram | N16: 786.66
A17: ORD200015 | B17: 45124 | C17: C39416 | D17: Printer | E17: 1 | F17: 473.96 | G17: 942 Main St | H17: Cash | I17: Delivered | J17: TRK54930938 | K17: 3 | M17: Google | N17: 473.96
A18: ORD200016 | B18: 44950 | C18: C28976 | D18: Printer | E18: 2 | F18: 533.81 | G18: 914 Main St | H18: Credit Card | I18: Pending | J18: TRK13194259 | K18: 3 | L18: FREESHIP | M18: Email | N18: 1067.62
A19: ORD200017 | B19: 45353 | C19: C60672 | D19: Tablet | E19: 1 | F19: 423.4 | G19: 382 Main St | H19: Debit Card | I19: Shipped | J19: TRK11972116 | K19: 3 | M19: Referral | N19: 423.4
A20: ORD200018 | B20: 45742 | C20: C84329 | D20: Desk | E20: 1 | F20: 431.44 | G20: 891 Main St | H20: Gift Card | I20: Pending | J20: TRK65191045 | K20: 3 | L20: SAVE10 | M20: Facebook | N20: 431.44
A21: ORD200019 | B21: 44949 | C21: C14552 | D21: Monitor | E21: 5 | F21: 224 | G21: 273 Main St | H21: Cash | I21: Returned | J21: TRK59101365 | K21: 9 | L21: SAVE10 | M21: Google | N21: 1120
A22: ORD200020 | B22: 45054 | C22: C54829 | D22: Chair | E22: 5 | F22: 62.51 | G22: 587 Main St | H22: Cash | I22: Pending | J22: TRK16718651 | K22: 9 | L22: WINTER15 | M22: Instagram | N22: 312.55
A23: ORD200021 | B23: 45613 | C23: C99023 | D23: Monitor | E23: 4 | F23: 342.95 | G23: 569 Main St | H23: Cash | I23: Delivered | J23: TRK52646983 | K23: 6 | M23: Google | N23: 1371.8
A24: ORD200022 | B24: 44955 | C24: C34416 | D24: Monitor | E24: 2 | F24: 49.62 | G24: 633 Main St | H24: Online | I24: Pending | J24: TRK75937350 | K24: 2 | L24: SAVE10 | M24: Google | N24: 99.24
A25: ORD200023 | B25: 45756 | C25: C42372 | D25: Phone | E25: 4 | F25: 273.25 | G25: 755 Main St | H25: Debit Card | I25: Cancelled | J25: TRK36168083 | K25: 5 | L25: FREESHIP | M25: Referral | N25: 1093
A26: ORD200024 | B26: 45595 | C26: C17470 | D26: Laptop | E26: 2 | F26: 230.95 | G26: 956 Main St | H26: Online | I26: Delivered | J26: TRK28775057 | K26: 3 | L26: WINTER15 | M26: Referral | N26: 461.9
A27: ORD200025 | B27: 45497 | C27: C42577 | D27: Monitor | E27: 1 | F27: 399.98 | G27: 709 Main St | H27: Debit Card | I27: Delivered | J27: TRK69423327 | K27: 3 | L27: WINTER15 | M27: Email | N27: 399.98
A28: ORD200026 | B28: 45357 | C28: C21944 | D28: Laptop | E28: 5 | F28: 59.55 | G28: 296 Main St | H28: Online | I28: Delivered | J28: TRK80276812 | K28: 6 | M28: Referral | N28: 297.75
A29: ORD200027 | B29: 45344 | C29: C97593 | D29: Printer | E29: 1 | F29: 472.74 | G29: 881 Main St | H29: Online | I29: Shipped | J29: TRK89117573 | K29: 6 | L29: WINTER15 | M29: Google | N29: 472.74
A30: ORD200028 | B30: 45251 | C30: C59823 | D30: Phone | E30: 4 | F30: 160.07 | G30: 568 Main St | H30: Online | I30: Pending | J30: TRK65895539 | K30: 5 | M30: Email | N30: 640.28
A31: ORD200029 | B31: 45555 | C31: C33260 | D31: Desk | E31: 3 | F31: 423.53 | G31: 930 Main St | H31: Credit Card | I31: Delivered | J31: TRK59744090 | K31: 6 | L31: SAVE10 | M31: Referral | N31: 1270.59
A32: ORD200030 | B32: 45738 | C32: C44267 | D32: Monitor | E32: 2 | F32: 426.7 | G32: 895 Main St | H32: Online | I32: Pending | J32: TRK54751444 | K32: 5 | L32: SAVE10 | M32: Referral | N32: 853.4
A33: ORD200031 | B33: 45107 | C33: C26445 | D33: Chair | E33: 3 | F33: 500.08 | G33: 996 Main St | H33: Debit Card | I33: Returned | J33: TRK31229981 | K33: 6 | M33: Facebook | N33: 1500.24
A34: ORD200032 | B34: 45047 | C34: C12388 | D34: Tablet | E34: 5 | F34: 536.72 | G34: 830 Main St | H34: Cash | I34: Delivered | J34: TRK99261395 | K34: 10 | M34: Email | N34: 2683.6
A35: ORD200033 | B35: 45082 | C35: C52184 | D35: Chair | E35: 1 | F35: 162.77 | G35: 912 Main St | H35: Online | I35: Cancelled | J35: TRK73312471 | K35: 4 | L35: WINTER15 | M35: Facebook | N35: 162.77
A36: ORD200034 | B36: 44933 | C36: C67195 | D36: Chair | E36: 4 | F36: 576.52 | G36: 926 Main St | H36: Credit Card | I36: Pending | J36: TRK55467915 | K36: 5 | L36: WINTER15 | M36: Facebook | N36: 2306.08
A37: ORD200035 | B37: 45633 | C37: C50304 | D37: Monitor | E37: 2 | F37: 465.15 | G37: 128 Main St | H37: Online | I37: Shipped | J37: TRK46850888 | K37: 2 | L37: SAVE10 | M37: Facebook | N37: 930.3
A38: ORD200036 | B38: 45785 | C38: C59337 | D38: Laptop | E38: 2 | F38: 534.43 | G38: 465 Main St | H38: Debit Card | I38: Pending | J38: TRK50961250 | K38: 5 | M38: Facebook | N38: 1068.86
A39: ORD200037 | B39: 45579 | C39: C10054 | D39: Laptop | E39: 2 | F39: 76.74 | G39: 409 Main St | H39: Cash | I39: Returned | J39: TRK94005261 | K39: 7 | L39: SAVE10 | M39: Instagram | N39: 153.48
A40: ORD200038 | B40: 45645 | C40: C15924 | D40: Laptop | E40: 1 | F40: 245.89 | G40: 549 Main St | H40: Debit Card | I40: Delivered | J40: TRK14835975 | K40: 3 | L40: SAVE10 | M40: Google | N40: 245.89
...

Sheet Cleaned Data
A1: OrderID | B1: Date | C1: CustomerID | D1: Product | E1: Quantity | F1: UnitPrice | G1: ShippingAddress | H1: PaymentMethod | I1: OrderStatus | J1: TrackingNumber | K1: ItemsInCart | L1: CouponCode | M1: ReferralSource | N1: TotalPrice | O1: Duplicate Check | P1: Trim Check | Q1: Price Check
A2: ORD200000 | B2: 44930 | C2: C72649 | D2: Monitor | E2: 5 | F2: 570.62 | G2: 928 Main St | H2: Debit Card | I2: Shipped | J2: TRK37947903 | K2: 7 | L2: SAVE10 | M2: Instagram | N2: 2853.1 | O2: =COUNTIF($A$2:A2,A2)>1 -> FALSE | P2: =TRIM(H2)=H2 -> TRUE | Q2: =ROUND(E2*F2,2)=ROUND(N2,2) -> TRUE
A3: ORD200001 | B3: 45527 | C3: C75739 | D3: Phone | E3: 2 | F3: 151.35 | G3: 823 Main St | H3: Online | I3: Shipped | J3: TRK91186779 | K3: 3 | L3: SAVE10 | M3: Referral | N3: 302.7 | O3: =COUNTIF($A$2:A3,A3)>1 -> FALSE | P3: =TRIM(H3)=H3 -> TRUE | Q3: =ROUND(E3*F3,2)=ROUND(N3,2) -> TRUE
A4: ORD200002 | B4: 45349 | C4: C81728 | D4: Tablet | E4: 5 | F4: 550.68 | G4: 512 Main St | H4: Credit Card | I4: Cancelled | J4: TRK42903982 | K4: 8 | L4: FREESHIP | M4: Email | N4: 2753.4 | O4: =COUNTIF($A$2:A4,A4)>1 -> FALSE | P4: =TRIM(H4)=H4 -> TRUE | Q4: =ROUND(E4*F4,2)=ROUND(N4,2) -> TRUE
A5: ORD200003 | B5: 45214 | C5: C33540 | D5: Chair | E5: 1 | F5: 273.19 | G5: 275 Main St | H5: Debit Card | I5: Returned | J5: TRK62788070 | K5: 5 | L5: SAVE10 | M5: Facebook | N5: 273.19 | O5: =COUNTIF($A$2:A5,A5)>1 -> FALSE | P5: =TRIM(H5)=H5 -> TRUE | Q5: =ROUND(E5*F5,2)=ROUND(N5,2) -> TRUE
A6: ORD200004 | B6: 45785 | C6: C81840 | D6: Printer | E6: 4 | F6: 626.01 | G6: 668 Main St | H6: Online | I6: Delivered | J6: TRK29241424 | K6: 8 | L6: SAVE10 | M6: Email | N6: 2504.04 | O6: =COUNTIF($A$2:A6,A6)>1 -> FALSE | P6: =TRIM(H6)=H6 -> TRUE | Q6: =ROUND(E6*F6,2)=ROUND(N6,2) -> TRUE
A7: ORD200005 | B7: 45222 | C7: C37249 | D7: Phone | E7: 2 | F7: 245.86 | G7: 934 Main St | H7: Credit Card | I7: Shipped | J7: TRK72976927 | K7: 4 | L7: SAVE10 | M7: Instagram | N7: 491.72 | O7: =COUNTIF($A$2:A7,A7)>1 -> FALSE | P7: =TRIM(H7)=H7 -> TRUE | Q7: =ROUND(E7*F7,2)=ROUND(N7,2) -> TRUE
A8: ORD200006 | B8: 45825 | C8: C83492 | D8: Laptop | E8: 1 | F8: 664.42 | G8: 986 Main St | H8: Gift Card | I8: Returned | J8: TRK96417362 | K8: 6 | L8: SAVE10 | M8: Facebook | N8: 664.42 | O8: =COUNTIF($A$2:A8,A8)>1 -> FALSE | P8: =TRIM(H8)=H8 -> TRUE | Q8: =ROUND(E8*F8,2)=ROUND(N8,2) -> TRUE
A9: ORD200007 | B9: 45058 | C9: C41460 | D9: Monitor | E9: 5 | F9: 149.55 | G9: 706 Main St | H9: Cash | I9: Shipped | J9: TRK78809193 | K9: 9 | L9: FREESHIP | M9: Facebook | N9: 747.75 | O9: =COUNTIF($A$2:A9,A9)>1 -> FALSE | P9: =TRIM(H9)=H9 -> TRUE | Q9: =ROUND(E9*F9,2)=ROUND(N9,2) -> TRUE
A10: ORD200008 | B10: 45749 | C10: C26817 | D10: Phone | E10: 2 | F10: 134.28 | G10: 904 Main St | H10: Gift Card | I10: Cancelled | J10: TRK61042692 | K10: 2 | L10: No Coupon | M10: Email | N10: 268.56 | O10: =COUNTIF($A$2:A10,A10)>1 -> FALSE | P10: =TRIM(H10)=H10 -> TRUE | Q10: =ROUND(E10*F10,2)=ROUND(N10,2) -> TRUE
A11: ORD200009 | B11: 45251 | C11: C31946 | D11: Desk | E11: 4 | F11: 509.38 | G11: 102 Main St | H11: Credit Card | I11: Shipped | J11: TRK33478363 | K11: 6 | L11: SAVE10 | M11: Google | N11: 2037.52 | O11: =COUNTIF($A$2:A11,A11)>1 -> FALSE | P11: =TRIM(H11)=H11 -> TRUE | Q11: =ROUND(E11*F11,2)=ROUND(N11,2) -> TRUE
A12: ORD200010 | B12: 45289 | C12: C43443 | D12: Tablet | E12: 5 | F12: 625.97 | G12: 333 Main St | H12: Credit Card | I12: Returned | J12: TRK98859248 | K12: 9 | L12: WINTER15 | M12: Instagram | N12: 3129.85 | O12: =COUNTIF($A$2:A12,A12)>1 -> FALSE | P12: =TRIM(H12)=H12 -> TRUE | Q12: =ROUND(E12*F12,2)=ROUND(N12,2) -> TRUE
A13: ORD200011 | B13: 45339 | C13: C93861 | D13: Monitor | E13: 3 | F13: 49.14 | G13: 831 Main St | H13: Online | I13: Returned | J13: TRK48234646 | K13: 7 | L13: SAVE10 | M13: Email | N13: 147.42 | O13: =COUNTIF($A$2:A13,A13)>1 -> FALSE | P13: =TRIM(H13)=H13 -> TRUE | Q13: =ROUND(E13*F13,2)=ROUND(N13,2) -> TRUE
... A1201: ORD201199 | B1201: 45088 | C1201: C57502 | D1201: Tablet | E1201: 4 | F1201: 560.58 | G1201: 201 Main St | H1201: Gift Card | I1201: Returned | J1201: TRK51116746 | K1201: 6 | L1201: SAVE10 | M1201: Referral | N1201: 2242.32 | O1201: =COUNTIF($A$2:A1201,A1201)>1 -> FALSE | P1201: =TRIM(H1201)=H1201 -> TRUE | Q1201: =ROUND(E1201*F1201,2)=ROUND(N1201,2) -> TRUE

Sheet Data Summary
A1: DATA CLEANING SUMMARY
A3: Rows and Columns
A4: Total rows (including header) | B4: 1201
A5: Total columns | B5: 17
A7: Missing Values
A8: CouponCode | B8: 309 blanks Values
A10: Duplicates
A11: 0 Duplicates | B11: Checked all 1,200 order ID for duplcates using COUNTIF
A13: Formatting and Cleaning actions taken.
A14: 1. Identified missing or null values which 309 blanks were found under CouponCode column
A15: 2. CouponCode 309 cell replaced with "No Coupon"
A16: 3. Check all dataset for duplicate under Order ID, Non was found
A17: 4. All text columns passed through TRIM() to remove any stray leading spaces.
A18: 5. Verified data columns stored as True dates not text
A19: 6. Verified numeric columns stored as True numbers
A21: Data Integrity Check:
A22: Verified TotalPrice = Quantity * UnitPrice for all the 1200 rows
A25: In Conclusion:
A26: I audited 1200 rows across (Excluding the header), 14 columns for missing values, duplicates, and formatting errors. The only issue found was 309 blank CouponCode values (25.75%), which I identified as customers who didn't use a coupon rather than lost data, and replaced with 'No Coupon' to make the missingness explicit. I verified no duplicate OrderIDs, confirmed dates and numbers were stored in correct formats, checked all text fields for hidden whitespace, and validated that TotalPrice matched Quantity × UnitPrice in every row with zero mismatches."

Sheet Analysis
A1: EXPLORATORY DATA ANALYSIS - PROJECT 2
A3: 1. Basic Statistics
A4: STATISTICS | B4: TOTAL PRICE | C4: QUANTITY | D4: UNIT PRICE
A5: Mean (Average) | B5: =AVERAGE('Cleaned Data'!N2:N1201) -> 1053.9683 | C5: =AVERAGE('Cleaned Data'!E2:E1201) -> 2.9458333 | D5: =AVERAGE('Cleaned Data'!F2:F1201) -> 356.41275
A6: Median | B6: =MEDIAN('Cleaned Data'!N2:N1201) -> 823.615 | C6: =MEDIAN('Cleaned Data'!E2:E1201) -> 3 | D6: =MEDIAN('Cleaned Data'!F1:F1201) -> 364.21
A7: Count | B7: =COUNT('Cleaned Data'!N2:N1201) -> 1200 | C7: =COUNT('Cleaned Data'!E2:E1201) -> 1200 | D7: =COUNT('Cleaned Data'!F2:F1201) -> 1200
A8: Minimum | B8: =MIN('Cleaned Data'!N2:N1201) -> 11.39 | C8: =MIN('Cleaned Data'!E2:E1201) -> 1 | D8: =MIN('Cleaned Data'!F2:F1201) -> 11.39
A9: Maximum | B9: =MAX('Cleaned Data'!N1:N1201) -> 3456.4 | C9: =MAX('Cleaned Data'!E1:E1201) -> 5 | D9: =MAX('Cleaned Data'!F1:F1201) -> 699.93
A10: Stan. Dev. | B10: =STDEV('Cleaned Data'!N1:N1201) -> 819.85656 | C10: =STDEV('Cleaned Data'!E1:E1201) -> 1.4075571 | D10: =STDEV('Cleaned Data'!F1:F1201) -> 197.17715
A12: 2. By Trends
A13: By Months (across all years)
A14: MONTH | B14: TOTAL PRICE | C14: ORDER COUNT | D14: AVERAGE ORDER VALUE
A15: January | B15: =SUMPRODUCT((MONTH('Cleaned Data'!$B$2:$B$1201)=MONTH(DATEVALUE(A15&" 1")))*'Cleaned Data'!$N$2:$N$1201) -> 124313.23 | C15: =SUMPRODUCT((MONTH('Cleaned Data'!$B$2:$B$1201)=MONTH(DATEVALUE(A15&" 1")))*1) -> 106 | D15: =B15/C15 -> 1172.7663
A16: February | B16: =SUMPRODUCT((MONTH('Cleaned Data'!$B$2:$B$1201)=MONTH(DATEVALUE(A16&" 1")))*'Cleaned Data'!$N$2:$N$1201) -> 112344.78 | C16: =SUMPRODUCT((MONTH('Cleaned Data'!$B$2:$B$1201)=MONTH(DATEVALUE(A16&" 1")))*1) -> 106 | D16: =B16/C16 -> 1059.8564
A17: March | B17: =SUMPRODUCT((MONTH('Cleaned Data'!$B$2:$B$1201)=MONTH(DATEVALUE(A17&" 1")))*'Cleaned Data'!$N$2:$N$1201) -> 123840.93 | C17: =SUMPRODUCT((MONTH('Cleaned Data'!$B$2:$B$1201)=MONTH(DATEVALUE(A17&" 1")))*1) -> 128 | D17: =B17/C17 -> 967.50727
A18: April | B18: =SUMPRODUCT((MONTH('Cleaned Data'!$B$2:$B$1201)=MONTH(DATEVALUE(A18&" 1")))*'Cleaned Data'!$N$2:$N$1201) -> 109186.05 | C18: =SUMPRODUCT((MONTH('Cleaned Data'!$B$2:$B$1201)=MONTH(DATEVALUE(A18&" 1")))*1) -> 113 | D18: =B18/C18 -> 966.24823
A19: May | B19: =SUMPRODUCT((MONTH('Cleaned Data'!$B$2:$B$1201)=MONTH(DATEVALUE(A19&" 1")))*'Cleaned Data'!$N$2:$N$1201) -> 135142.59 | C19: =SUMPRODUCT((MONTH('Cleaned Data'!$B$2:$B$1201)=MONTH(DATEVALUE(A19&" 1")))*1) -> 120 | D19: =B19/C19 -> 1126.1882
A20: June | B20: =SUMPRODUCT((MONTH('Cleaned Data'!$B$2:$B$1201)=MONTH(DATEVALUE(A20&" 1")))*'Cleaned Data'!$N$2:$N$1201) -> 170616.13 | C20: =SUMPRODUCT((MONTH('Cleaned Data'!$B$2:$B$1201)=MONTH(DATEVALUE(A20&" 1")))*1) -> 147 | D20: =B20/C20 -> 1160.6539
A21: July | B21: =SUMPRODUCT((MONTH('Cleaned Data'!$B$2:$B$1201)=MONTH(DATEVALUE(A21&" 1")))*'Cleaned Data'!$N$2:$N$1201) -> 85784.64 | C21: =SUMPRODUCT((MONTH('Cleaned Data'!$B$2:$B$1201)=MONTH(DATEVALUE(A21&" 1")))*1) -> 87 | D21: =B21/C21 -> 986.03034
A22: August | B22: =SUMPRODUCT((MONTH('Cleaned Data'!$B$2:$B$1201)=MONTH(DATEVALUE(A22&" 1")))*'Cleaned Data'!$N$2:$N$1201) -> 86343.21 | C22: =SUMPRODUCT((MONTH('Cleaned Data'!$B$2:$B$1201)=MONTH(DATEVALUE(A22&" 1")))*1) -> 79 | D22: =B22/C22 -> 1092.952
A23: September | B23: =SUMPRODUCT((MONTH('Cleaned Data'!$B$2:$B$1201)=MONTH(DATEVALUE(A23&" 1")))*'Cleaned Data'!$N$2:$N$1201) -> 69321.65 | C23: =SUMPRODUCT((MONTH('Cleaned Data'!$B$2:$B$1201)=MONTH(DATEVALUE(A23&" 1")))*1) -> 73 | D23: =B23/C23 -> 949.61164
A24: October | B24: =SUMPRODUCT((MONTH('Cleaned Data'!$B$2:$B$1201)=MONTH(DATEVALUE(A24&" 1")))*'Cleaned Data'!$N$2:$N$1201) -> 89834.82 | C24: =SUMPRODUCT((MONTH('Cleaned Data'!$B$2:$B$1201)=MONTH(DATEVALUE(A24&" 1")))*1) -> 78 | D24: =B24/C24 -> 1151.7285
A25: November | B25: =SUMPRODUCT((MONTH('Cleaned Data'!$B$2:$B$1201)=MONTH(DATEVALUE(A25&" 1")))*'Cleaned Data'!$N$2:$N$1201) -> 75493.43 | C25: =SUMPRODUCT((MONTH('Cleaned Data'!$B$2:$B$1201)=MONTH(DATEVALUE(A25&" 1")))*1) -> 76 | D25: =B25/C25 -> 993.33461
A26: December | B26: =SUMPRODUCT((MONTH('Cleaned Data'!$B$2:$B$1201)=MONTH(DATEVALUE(A26&" 1")))*'Cleaned Data'!$N$2:$N$1201) -> 82540.5 | C26: =SUMPRODUCT((MONTH('Cleaned Data'!$B$2:$B$1201)=MONTH(DATEVALUE(A26&" 1")))*1) -> 87 | D26: =B26/C26 -> 948.74138
A28: 2. By Product
A29: By Months (across all years)
A30: PRODUCT | B30: TOTAL SALES | C30: ORDER COUNT | D30: AVERAGE ORDER VALUE
A31: Chair | B31: =SUMIF('Cleaned Data'!$D$2:$D$1201,A31,'Cleaned Data'!$N$2:$N$1201) -> 195620.11 | C31: =COUNTIF('Cleaned Data'!$D$2:$D$1201,A31) -> 178 | D31: =B31/C31 -> 1098.9894
A32: Desk | B32: =SUMIF('Cleaned Data'!$D$2:$D$1201,A32,'Cleaned Data'!$N$2:$N$1201) -> 167459.93 | C32: =COUNTIF('Cleaned Data'!$D$2:$D$1201,A32) -> 170 | D32: =B32/C32 -> 985.05841
A33: Laptop | B33: =SUMIF('Cleaned Data'!$D$2:$D$1201,A33,'Cleaned Data'!$N$2:$N$1201) -> 192126.56 | C33: =COUNTIF('Cleaned Data'!$D$2:$D$1201,A33) -> 173 | D33: =B33/C33 -> 1110.5582
A34: Monitor | B34: =SUMIF('Cleaned Data'!$D$2:$D$1201,A34,'Cleaned Data'!$N$2:$N$1201) -> 175651.41 | C34: =COUNTIF('Cleaned Data'!$D$2:$D$1201,A34) -> 163 | D34: =B34/C34 -> 1077.616
A35: Phone | B35: =SUMIF('Cleaned Data'!$D$2:$D$1201,A35,'Cleaned Data'!$N$2:$N$1201) -> 151722.39 | C35: =COUNTIF('Cleaned Data'!$D$2:$D$1201,A35) -> 156 | D35: =B35/C35 -> 972.57942
A36: Printer | B36: =SUMIF('Cleaned Data'!$D$2:$D$1201,A36,'Cleaned Data'!$N$2:$N$1201) -> 195612.61 | C36: =COUNTIF('Cleaned Data'!$D$2:$D$1201,A36) -> 181 | D36: =B36/C36 -> 1080.7327
A37: Tablet | B37: =SUMIF('Cleaned Data'!$D$2:$D$1201,A37,'Cleaned Data'!$N$2:$N$1201) -> 186568.95 | C37: =COUNTIF('Cleaned Data'!$D$2:$D$1201,A37) -> 179 | D37: =B37/C37 -> 1042.2846
A39: 3. Outliers (IRQ Method) - TotalPrice
A40: Q1 (25th percentile) | B40: =QUARTILE('Cleaned Data'!N2:N1201,1) -> 410.52
A41: Q3 (75th percentile) | B41: =QUARTILE('Cleaned Data'!N2:N1201,3) -> 1578.475
A42: IQR (Q3 - Q1) | B42: =B41-B40 -> 1167.955
A43: Lower Bound (Q1 - 1.5xIQR) | B43: =B40-1.5*B42 -> -1341.4125
A44: Upper Bound (Q3 + 1.5xIQR) | B44: =B41+1.5*B42 -> 3330.4075
...
